<?xml version="1.0"?>  
<robot name="racebot">  


  <link name="base_footprint"/>

  <joint name="base_joint" type="fixed">
    <parent link="base_footprint"/>
    <child link="base_link"/>
    <origin xyz="0.0 0.0 0.11" rpy="0 0 0"/>
  </joint>

  <link name="base_link">  
    <visual>  
      <geometry>  
        <box size="0.27 0.27 0.2"/>  
      </geometry>  
    <origin rpy="0 0 0" xyz="0 0 0"/>  
    <material name="blue">  
        <color rgba="0 191 255 1"/>  
    </material>  
    </visual>  

  </link>  

 

<link name="right_front_wheel">  

    <visual>  
      <origin xyz="0 0 0" rpy="1.57 0 0"/>
      <geometry>  
        <cylinder length=".018" radius="0.0325"/>  
      </geometry>  

      <material name="black">  
        <color rgba="0 0 0 1"/>  
      </material>  
    </visual>  

  </link>  

 

  <joint name="right_front_wheel_joint" type="continuous">  

    <axis xyz="0 0 1"/>  

    <parent link="base_link"/>  

    <child link="right_front_wheel"/>  

    <origin rpy="0 0 0" xyz="0.055 0.139 -0.0775"/>
  
    <limit effort="100" velocity="100"/>  

    <joint_properties damping="0.0" friction="0.0"/>  

  </joint>  


<link name="left_front_wheel">  

    <visual>  
      <origin xyz="0 0 0" rpy="1.57 0 0"/>
      <geometry>  
        <cylinder length=".018" radius="0.0325"/>  
      </geometry>  

      <material name="black">  
        <color rgba="0 0 0 1"/>  
      </material>  
    </visual>  

  </link>  

 

  <joint name="left_front_wheel_joint" type="continuous">  

    <axis xyz="0 0 1"/>  
    <parent link="base_link"/>  
    <child link="left_front_wheel"/>  
    <origin rpy="0 0 0" xyz="0.055 -0.139 -0.0775"/>  
    <limit effort="100" velocity="100"/>  
    <joint_properties damping="0.0" friction="0.0"/>  

  </joint>  


 <link name="laser">
    <visual>
      <geometry>
        <cylinder length=".08" radius="0.05"/>
      </geometry>
      <material name="orange">
          <color rgba="255 108 10  1"/>
      </material>
    </visual>
  </link>

  <joint name="laser_joint" type="fixed">
    <parent link="base_link"/>
    <child link="laser"/>
    <origin rpy="0 0 0" xyz="0 0 0.14"/>
  </joint>


</robot> 
